#VRML_SIM R2023b utf8

EXTERNPROTO "https://raw.githubusercontent.com/cyberbotics/webots/R2023b/projects/appearances/protos/OsbWood.proto"
EXTERNPROTO "https://raw.githubusercontent.com/cyberbotics/webots/R2023b/projects/objects/floors/protos/RectangleArena.proto"
EXTERNPROTO "https://raw.githubusercontent.com/cyberbotics/webots/R2023b/projects/objects/backgrounds/protos/TexturedBackground.proto"
EXTERNPROTO "https://raw.githubusercontent.com/cyberbotics/webots/R2023b/projects/objects/backgrounds/protos/TexturedBackgroundLight.proto"

WorldInfo {
  info [
    "In this example, the robot moves down a slope."
    "The altimeter is used to record the robots height."
  ]
  title "Altimeter"
  basicTimeStep 8
  contactProperties [
    ContactProperties {
      material2 "body"
      coulombFriction [
        0
      ]
      softCFM 0.1
    }
  ]
}
Viewpoint {
  orientation -0.4354381403021371 -0.6217535013937647 0.6510116815194718 4.8025156217916605
  position -0.2972407924620892 0.3245023051894575 0.8413069152306539
}
TexturedBackground {
}
TexturedBackgroundLight {
}
RectangleArena {
}
PointLight {
  attenuation 0 0 1
  intensity 0.6
  location 0.6 0 0
}
DEF SLOPE Solid {
  translation 0 0 0.15
  rotation 0 1 0 -0.4
  children [
    Shape {
      appearance OsbWood {
        textureTransform TextureTransform {
          scale 0.5 2
        }
      }
      geometry DEF BOX0 Box {
        size 0.8 0.2 0.02
      }
    }
  ]
  name "green box"
  boundingObject USE BOX0
}
Robot {
  translation -0.23824969674252505 3.117937788079078e-05 0.06023193722616263
  rotation -0.24582882932842626 2.4568442915010023e-05 0.9693132548703783 -3.1413349243454367
  children [
    Altimeter {
    }
    Pose {
      translation 0 0 0.0415
      children [
        Shape {
          appearance PBRAppearance {
            baseColor 0.0820075 0.364731 0.8
            roughness 1
            metalness 0
          }
          geometry DEF BODY Cylinder {
            height 0.08
            radius 0.045
          }
        }
      ]
    }
    HingeJoint {
      jointParameters HingeJointParameters {
        position 21.695836821394415
        axis 0 1 0
        anchor 0 0 0.025
      }
      device [
        RotationalMotor {
          name "left wheel motor"
          consumptionFactor 70
        }
        PositionSensor {
          name "left wheel sensor"
        }
      ]
      endPoint Solid {
        translation 0 0.044999999999999825 0.025
        rotation 0.5115757844891475 -0.5115758555429644 0.6903479997434608 4.35003006013505
        children [
          DEF WHEEL Pose {
            rotation 0.577656895078166 0.5771968951617173 -0.5771968951617173 -2.093935
            children [
              Shape {
                appearance PBRAppearance {
                  baseColor 1 0 0
                  roughness 1
                  metalness 0
                }
                geometry Cylinder {
                  height 0.01
                  radius 0.025
                }
              }
            ]
          }
        ]
        name "left wheel"
        boundingObject USE WHEEL
        physics DEF PHYSICS_WHEEL Physics {
          density -1
          mass 0.05
        }
        linearVelocity -0.04606500398868888 -1.3011923264731374e-05 -0.019475786318625954
        angularVelocity 0.0004746649247090885 -2.0000031373974685 0.000213937863621608
      }
    }
    HingeJoint {
      jointParameters HingeJointParameters {
        position 21.69583685641714
        axis 0 1 0
        anchor 0 0 0.025
      }
      device [
        RotationalMotor {
          name "right wheel motor"
          consumptionFactor 70
        }
        PositionSensor {
          name "right wheel sensor"
        }
      ]
      endPoint Solid {
        translation 0 -0.04499999999999999 0.025
        rotation 0.5115757934142887 -0.5115758644681058 0.6903479865156784 4.350030042218269
        children [
          USE WHEEL
        ]
        boundingObject USE WHEEL
        physics USE PHYSICS_WHEEL
        linearVelocity -0.04606427340739072 -1.3011759347423608e-05 -0.019475857634393537
        angularVelocity 0.00047462156838300683 -2.000003126517885 0.00021387194596979945
      }
    }
    DistanceSensor {
      translation 0.042 0.02 0.063
      rotation 0 0 -1 -0.499205
      children [
        DEF SENSOR Pose {
          rotation 0.577656895078166 0.5771968951617173 -0.5771968951617173 -2.093935
          children [
            Shape {
              appearance PBRAppearance {
                baseColor 0.975691 0.981481 0.0252992
                roughness 1
                metalness 0
              }
              geometry Cylinder {
                height 0.004
                radius 0.008
              }
            }
          ]
        }
      ]
      name "ds0"
      lookupTable [
        0 1024 0
        0.05 1024 0
        0.15 0 0
      ]
      numberOfRays 2
      aperture 1
    }
    DistanceSensor {
      translation 0.042 -0.02 0.063
      rotation 0 0 1 -0.500795
      children [
        USE SENSOR
      ]
      name "ds1"
      lookupTable [
        0 1024 0
        0.05 1024 0
        0.15 0 0
      ]
      numberOfRays 2
      aperture 1
    }
    DEF SMILE Pose {
      translation 0.036 0 0.025
      rotation 0.25056300542381216 -0.9351130202419243 -0.25056300542381216 1.637834
      children [
        Shape {
          appearance PBRAppearance {
            baseColor 0.721569 0.290196 0.290196
            roughness 1
            metalness 0
          }
          geometry Cylinder {
            height 0.018
            radius 0.009
            subdivision 3
          }
        }
      ]
    }
  ]
  name "MyBot"
  contactMaterial "body"
  boundingObject Pose {
    translation 0 0 0.0415
    rotation 0 0 1 -1.570796
    children [
      USE BODY
    ]
  }
  physics Physics {
    density -1
    mass 0.5
  }
  controller "my_controller"
  linearVelocity -0.04606468098965181 -1.2935406288922369e-05 -0.019475844865734927
  angularVelocity -8.971037895652326e-07 -2.914304984955347e-06 -8.065427541913173e-06
}
